Workbook

Sheet Raw Data
A1: Order ID | B1: Order Date | C1: Ship Date | D1: Customer ID | E1: Customer Name | F1: Segment | G1: City | H1: State | I1: Region | J1: Product Category | K1: Sub Category | L1: Product Name | M1: Sales | N1: Quantity | O1: Discount | P1: Profit | Q1: Shipping Cost | R1: Payment Mode | S1: Order Priority
A2: ORD-7979 | B2: 31-Dec-2023 | C2: 07/01/2024 | D2: CUST-2075 | E2: Brandon Kelly | F2: Consumer | G2: Columbus | H2: Ohio | I2: Central | J2: technology | K2: Copiers | L2: Compact Copier | M2: 156.38 | N2: 2 | O2: 0.1 | P2: 31.11 | Q2: 48.55 | R2: Credit Card | S2: Low
A3: ORD-12072 | B3: 2026-04-18 | C3: 23-Apr-2026 | D3: CUST-2159 | E3: Kara Sandoval | F3: Corporate | G3: Miami | H3: Florida | I3: East | J3: furniture | K3: Chairs | L3: Ergonomic Office Chair | M3: 986.48 | N3: 8 | O3: 0.3 | P3: -102.9 | Q3: 30.77 | R3: DEBIT CARD | S3: Low
A4: ORD-6756 | B4: 15-Dec-2024 | C4: 12-22-2024 | D4: CUST-1337 | F4: Corporate | G4: Birmingham | H4: Alabama | I4: South | J4: Furniture | K4: Bookcases | L4: Oak Bookcase | M4: $1162.5 | N4: 3 | O4: 0.3 | P4: 66.88 | Q4: 44.8 | R4: upi | S4: High
A5: ORD-12634 | B5: 09-Dec-2023 | C5: 14/12/2023 | D5: CUST-1873 | E5: Amy Miller | F5: Home Office | G5: Albany | H5: New York | I5: East | J5: furniture | K5: Furnishings | L5: Desk Lamp | M5: 206.7 | N5: 3 | O5: 0.3 | P5: -4.43 | Q5: 37.99 | R5: UPI | S5: Critical
A6: ORD-14527 | B6: 30-Oct-2025 | C6: 10-31-2025 | D6: CUST-1855 | E6: Melissa Abbott | F6: CORPORATE | G6: Norfolk | H6: Virginia | I6: East | J6: Technology | K6: Accessories | L6: Laptop Stand | M6: 6846.35 | N6: 7 | O6: 0 | P6: 1973.68 | Q6: 57.6 | R6: Debit Card | S6: Low
A7: ORD-4886 | B7: 01-19-2026 | C7: 2026-01-22 | D7: CUST-1260 | E7: Katie Suarez | F7: Home Office | G7: Richmond | H7: Virginia | I7: East | J7: Office Supplies | K7: Art | L7: Sketch Pad | M7: 209.4 | N7: 12 | O7: 0 | Q7: 11.11 | R7: UPI | S7: Critical
A8: ORD-5268 | B8: 18-Sep-2023 | C8: 09-22-2023 | D8: CUST-1723 | E8: Todd Reynolds | F8: corporate | G8: Las Vegas | H8: Nevada | I8: West | J8: Furniture | K8: Furnishings | L8: Wall Clock | M8: 2705.92 | N8: 7 | O8: 0 | P8: 1214.63 | Q8: 58.08 | R8: debit card | S8: Medium
A9: ORD-12605 | B9: 18/08/2023 | C9: 08-20-2023 | D9: CUST-1028 | E9: Zachary Hicks | F9: Consumer | G9: San Antonio | H9: Texas | I9: Central | J9: Technology | K9: Machines | L9: Laser Printer | M9: 3137.44 | N9: 8 | O9: 0 | P9: 1380.59 | Q9: 7.77 | R9: CREDIT CARD | S9: Critical
A10: ORD-11390 | B10: 02/04/2026 | C10: 04-09-2026 | D10: CUST-1917 | E10: Christine Parker | F10: Corporate | G10: Worcester | H10: Massachusetts | I10: East | J10: OFFICE SUPPLIES | K10: Fasteners | L10: Push Pins | M10: 110.97 | N10: 9 | O10: 0 | P10: 19.56 | Q10: 8.14 | R10: Net Banking | S10: Low
A11: ORD-7268 | B11: 08/03/2026 | C11: 2026-03-12 | D11: CUST-1136 | E11: Robert Potter | F11: Consumer | G11: Lexington | H11: Kentucky | I11: South | J11: Office Supplies | K11: Storage | L11: Filing Cabinet | M11: 104.91 | N11: 3 | O11: 0.1 | P11: 27.54 | Q11: 4.63 | R11: upi | S11: Medium
A12: ORD-13637 | B12: 26/05/2025 | C12: 05-31-2025 | D12: CUST-2207 | E12: Dawn Rivera | F12: consumer | G12: springfield | H12: Illinois | I12: Central | J12: Office Supplies | K12: Art | L12: Colored Pencils | M12: 24.37 | N12: 1 | O12: 0.5 | P12: -5.2 | Q12: 37.44 | R12: UPI | S12: Low
A13: ORD-11892 | B13: 10-18-2023 | C13: 10-25-2023 | D13: CUST-1437 | E13: Christopher Guerra | F13: Consumer | G13: St. Louis | H13: Missouri | I13: Central | J13: furniture | K13: Furnishings | L13: Wall Clock | M13: 1051.92 | N13: 9 | O13: 0 | P13: 360.56 | Q13: 37.53 | R13: Cash on Delivery | S13: Medium
A14: ORD-7643 | B14: 12-27-2023 | C14: 28/12/2023 | D14: CUST-1112 | E14: Julia Torres | F14: Consumer | G14: San Francisco | H14: California | I14: West | J14: Office Supplies | K14: Labels | L14: Shipping Labels | M14: 145.8 | N14: 12 | O14: 0.1 | P14: 19.16 | Q14: 6.82 | R14: Debit Card | S14: Low
A15: ORD-14512 | B15: 05-02-2026 | C15: 05-07-2026 | D15: CUST-1382 | E15: Douglas Gregory | F15: HOME OFFICE | G15: Las Vegas | H15: Nevada | I15: West | J15: OFFICE SUPPLIES | K15: Storage | L15: Filing Cabinet | M15: 187.8 | N15: 6 | P15: 31.08 | Q15: 58.29 | R15: credit card | S15: High
A16: ORD-16774 | B16: 12-Mar-2024 | C16: 03-16-2024 | D16: CUST-1825 | E16: Monica Ellis | F16: consumer | G16: Chicago | H16: Illinois | I16: Central | J16: Furniture | K16: Chairs | L16: Ergonomic Office Chair | M16: 1286.73 | N16: 3 | O16: 0 | P16: 293.05 | Q16: 38.99 | R16: net banking | S16: Medium
A17: ORD-8475 | B17: 2025-03-28 | C17: 03-31-2025 | D17: CUST-1274 | E17: Joyce Bowen | F17: CONSUMER | G17: Eugene | H17: Oregon | I17: West | J17: Office Supplies | K17: Paper | L17: Copy Paper A4 | M17: 61.66 | N17: 2 | O17: 0.15 | P17: 5.17 | Q17: 43.94 | R17: CASH ON DELIVERY | S17: Critical
A18: ORD-15479 | B18: 29/10/2023 | C18: 11-01-2023 | D18: CUST-1133 | E18: Daniel Kennedy | F18: Corporate | G18: DULUTH | H18: Minnesota | I18: Central | J18: OFFICE SUPPLIES | K18: Art | L18: Marker Set | M18: 248.78 | N18: 7 | O18: 0.5 | P18: -29.59 | Q18: 56.2 | R18: Debit Card | S18: Medium
A19: ORD-9695 | B19: 12/10/2023 | C19: 2023-10-19 | D19: CUST-1606 | E19: Brian Martin | F19: CORPORATE | G19: Lexington | H19: Kentucky | I19: South | J19: Office Supplies | K19: Fasteners | L19: Push Pins | M19: 122.48 | N19: 8 | O19: 0 | P19: 46.05 | Q19: 4.49 | R19: Debit Card | S19: Low
A20: ORD-17400 | B20: 07/07/2024 | C20: 12-Jul-2024 | D20: CUST-2164 | E20: Mitchell Griffith | F20: corporate | G20: Newark | H20: New Jersey | I20: East | J20: OFFICE SUPPLIES | K20: Labels | L20: Address Labels | M20: 112.59 | N20: 9 | O20: 0.2 | P20: 8.53 | Q20: 3.12 | R20: Debit Card | S20: Low
A21: ORD-13169 | B21: 2025-10-01 | C21: 10-02-2025 | D21: CUST-1803 | E21: Rodney Williams | F21: CONSUMER | G21: LEXINGTON | H21: Kentucky | I21: South | J21: technology | K21: Phones | L21: Wireless Headset | M21: 3389.76 | N21: 11 | O21: 0 | P21: 743.62 | Q21: 10.44 | R21: UPI | S21: Low
A22: ORD-3764 | B22: 2024-07-20 | C22: 2024-07-23 | D22: CUST-1983 | E22: Sean Curtis | F22: consumer | G22: savannah | H22: Georgia | I22: South | J22: FURNITURE | K22: Furnishings | L22: Desk Lamp | M22: 83.05 | N22: 11 | O22: 0.5 | P22: -9.58 | Q22: 5.4 | R22: Net Banking | S22: High
A23: ORD-14619 | B23: 13-Jul-2026 | C23: 2026-07-20 | D23: CUST-2237 | E23: Nicole Richards | F23: Home Office | G23: Miami | H23: Florida | I23: East | J23: technology | K23: Machines | L23: Shredder | M23: 1946.34 | N23: 2 | O23: 0.3 | P23: -5.12 | Q23: 50.37 | R23: net banking | S23: Medium
A24: ORD-3648 | B24: 07-07-2025 | C24: 07-10-2025 | D24: CUST-1740 | E24: Eric Rush | F24: Corporate | G24: denver | H24: Colorado | I24: West | J24: technology | K24: Machines | L24: Label Maker | M24: 8933.16 | N24: 12 | O24: 0.5 | P24: -2067.26 | Q24: 15.82 | R24: CASH ON DELIVERY | S24: Low
A25: ORD-14198 | B25: 01-26-2026 | C25: 30-Jan-2026 | D25: CUST-2142 | E25: Joseph Haynes | F25: Home Office | G25: Boulder | H25: Colorado | I25: West | J25: Office Supplies | K25: Storage | L25: Drawer Organizer | M25: 180.18 | N25: 11 | O25: 0.3 | P25: -4.48 | Q25: 12.5 | R25: Credit Card | S25: Medium
A26: ORD-5050 | B26: 2023-12-24 | C26: 25/12/2023 | D26: CUST-2086 | E26: Mark Smith | F26: consumer | G26: Cleveland | H26: Ohio | I26: Central | J26: furniture | K26: Tables | L26: Round Conference Table | M26: 2560.77 | N26: 9 | O26: 0 | P26: 477.24 | Q26: 3.22 | R26: net banking | S26: Critical
A27: ORD-5598 | B27: 11-09-2023 | C27: 14-Nov-2023 | D27: CUST-1870 | E27: Kimberly Myers | F27: Home Office | G27: Charlotte | H27: North Carolina | I27: South | J27: Technology | K27: Phones | L27: Wireless Headset | M27: 2583.28 | N27: 4 | O27: 0.4 | P27: -642.87 | Q27: 39.79 | R27: UPI | S27: Medium
... A32: ORD-8173 | B32: 2026-07-02 | C32: 2026-07-03 | D32: CUST-1715 | E32: David Davenport | F32: Consumer | G32: Austin | H32: Texas | I32: Central | J32: furniture | K32: Tables | L32: Round Conference Table | M32: 1516.88 | N32: 8 | O32: 0 | P32: 576.56 | Q32: 23.67 | R32: NET BANKING | S32: Low
A33: ORD-7264 | B33: 08/12/2025 | C33: 2025-12-15 | D33: CUST-1972 | E33: Amanda Guzman | F33: consumer | G33: Savannah | H33: Georgia | I33: South | J33: Technology | K33: Machines | L33: Shredder | M33: 2208.4 | N33: 4 | O33: 0.4 | Q33: 6.7 | R33: Debit Card | S33: High
A34: ORD-17402 | B34: 04/01/2026 | C34: 06/01/2026 | D34: CUST-1112 | E34: Julia Torres | F34: CONSUMER | G34: LOUISVILLE | H34: Kentucky | I34: South | J34: Office Supplies | K34: Storage | L34: Filing Cabinet | M34: 47.08 | N34: 4 | O34: 0.15 | P34: 11.63 | Q34: 43.44 | R34: credit card | S34: Medium
A35: ORD-9978 | B35: 03-10-2026 | C35: 2026-03-11 | D35: CUST-1556 | E35: Kathryn Williams | F35: CORPORATE | G35: Jersey City | H35: New Jersey | I35: East | J35: TECHNOLOGY | K35: Phones | L35: Smartphone X200 | M35: 1969.28 | N35: 4 | O35: 0.15 | P35: 513.27 | Q35: 16.51 | R35: Debit Card | S35: Critical
A36: ORD-11153 | B36: 2025-11-02 | C36: 05/11/2025 | D36: CUST-1537 | E36: Bianca Wood | F36: consumer | G36: Columbus | H36: Ohio | I36: Central | J36: furniture | K36: Chairs | L36: Folding Chair | M36: 764.4 | N36: 7 | O36: 0.5 | P36: -60.56 | Q36: 41.82 | R36: debit card | S36: Low
A37: ORD-17764 | B37: 24/06/2026 | C37: 06-29-2026 | D37: CUST-2140 | E37: Patricia Ray | F37: corporate | G37: LEXINGTON | H37: Kentucky | I37: South | J37: OFFICE SUPPLIES | K37: Art | L37: Colored Pencils | M37: 69.0 | N37: 10 | O37: 0 | P37: 10.69 | Q37: 6.6 | R37: UPI | S37: Low
A38: ORD-5157 | B38: 2024-03-02 | C38: 09/03/2024 | D38: CUST-2351 | E38: Timothy Andrews | F38: Home Office | G38: TACOMA | H38: Washington | I38: West | J38: Furniture | K38: Chairs | L38: Ergonomic Office Chair | M38: 564.12 | N38: 3 | O38: 0.2 | P38: 60.1 | Q38: 20.39 | R38: CREDIT CARD | S38: High
A39: ORD-3693 | B39: 11-Aug-2025 | C39: 08-14-2025 | D39: CUST-1458 | E39: Aaron Miller | F39: Corporate | G39: Ann Arbor | H39: Michigan | I39: Central | J39: Technology | K39: Copiers | L39: Office Copier A3 | M39: 3102.93 | N39: 9 | O39: 0.15 | P39: 681.77 | Q39: 40.2 | R39: CASH ON DELIVERY | S39: Medium
A40: ORD-16483 | B40: 2024-09-30 | C40: 10-01-2024 | D40: CUST-1675 | E40: Larry Harris | F40: Consumer | G40: Savannah | H40: Georgia | I40: South | J40: technology | K40: Accessories | L40: Laptop Stand | M40: 1843.87 | N40: 7 | O40: 0.2 | P40: 149.62 | Q40: 8.26 | R40: credit card | S40: Medium
A41: ORD-3153 | B41: 01-Oct-2025 | C41: 03-Oct-2025 | D41: CUST-1298 | E41: Keith Jennings | F41: Home Office | G41: Worcester | H41: Massachusetts | I41: East | J41: office supplies | K41: Binders | L41: Heavy Duty Binder | M41: 48.7 | N41: 1 | O41: 0.15 | P41: 6.53 | Q41: 35.87 | R41: Debit Card | S41: Medium
A42: ORD-18178 | B42: 15-Apr-2024 | C42: 2024-04-20 | D42: CUST-1083 | E42: Paul Jones | F42: consumer | G42: kansas city | H42: Missouri | I42: Central | J42: Furniture | K42: Tables | L42: Adjustable Height Table | M42: 6182.82 | N42: 9 | O42: 0.3 | P42: -98.04 | Q42: 11.91 | R42: UPI | S42: Low
A43: ORD-3758 | B43: 07-24-2024 | C43: 2024-07-31 | D43: CUST-2132 | E43: Michael Brown | F43: consumer | G43: SEATTLE | H43: Washington | I43: West | J43: Technology | K43: Machines | L43: Label Maker | M43: 312.56 | N43: 4 | O43: 0 | P43: 105.73 | Q43: 49.35 | R43: debit card | S43: Critical
A44: ORD-8364 | B44: 26-Oct-2023 | C44: 28-Oct-2023 | D44: CUST-2061 | E44: Shannon Green | F44: HOME OFFICE | G44: Boulder | H44: Colorado | I44: West | J44: office supplies | K44: Paper | L44: Copy Paper A4 | M44: 168.14 | N44: 7 | O44: 0.3 | P44: -18.73 | Q44: 43.73 | R44: UPI | S44: Medium
...

Sheet Cleaning Formulas
A1: Order ID | B1: Order Date (Cleaned) | C1: Customer Name (Filled) | D1: City (Trimmed/Proper) | E1: Sales (Numeric) | F1: Discount (Filled) | G1: Profit (Rounded) | H1: Order Priority (Filled) | I1: Order Value Tier
A2: ='Raw Data'!A2 -> ORD-7979 | B2: =IFERROR(DATEVALUE('Raw Data'!B2),"Check Format") -> 45291 | C2: =IF('Raw Data'!E2="",IFERROR(INDEX('Raw Data'!$E$2:$E$501,MATCH('Raw Data'!D2,'Raw Data'!$D$2:$D$501,0)),"Unknown Customer"),'Raw Data'!E2) -> Brandon Kelly | D2: =PROPER(TRIM('Raw Data'!G2)) -> Columbus | E2: =ROUND(VALUE(SUBSTITUTE(TRIM('Raw Data'!M2),"$","")),2) -> 156.38 | F2: =IF('Raw Data'!O2="",0,'Raw Data'!O2) -> 0.1 | G2: =ROUND('Raw Data'!P2,2) -> 31.11 | H2: =IF('Raw Data'!S2="","Medium",'Raw Data'!S2) -> Low | I2: =IF(E2<100,"Small",IF(E2<500,"Medium",IF(E2<1500,"Large","Very Large"))) -> Medium
A3: ='Raw Data'!A3 -> ORD-12072 | B3: =IFERROR(DATEVALUE('Raw Data'!B3),"Check Format") -> 46130 | C3: =IF('Raw Data'!E3="",IFERROR(INDEX('Raw Data'!$E$2:$E$501,MATCH('Raw Data'!D3,'Raw Data'!$D$2:$D$501,0)),"Unknown Customer"),'Raw Data'!E3) -> Kara Sandoval | D3: =PROPER(TRIM('Raw Data'!G3)) -> Miami | E3: =ROUND(VALUE(SUBSTITUTE(TRIM('Raw Data'!M3),"$","")),2) -> 986.48 | F3: =IF('Raw Data'!O3="",0,'Raw Data'!O3) -> 0.3 | G3: =ROUND('Raw Data'!P3,2) -> -102.9 | H3: =IF('Raw Data'!S3="","Medium",'Raw Data'!S3) -> Low | I3: =IF(E3<100,"Small",IF(E3<500,"Medium",IF(E3<1500,"Large","Very Large"))) -> Large
A4: ='Raw Data'!A4 -> ORD-6756 | B4: =IFERROR(DATEVALUE('Raw Data'!B4),"Check Format") -> 45641 | C4: =IF('Raw Data'!E4="",IFERROR(INDEX('Raw Data'!$E$2:$E$501,MATCH('Raw Data'!D4,'Raw Data'!$D$2:$D$501,0)),"Unknown Customer"),'Raw Data'!E4) -> 0 | D4: =PROPER(TRIM('Raw Data'!G4)) -> Birmingham | E4: =ROUND(VALUE(SUBSTITUTE(TRIM('Raw Data'!M4),"$","")),2) -> 1162.5 | F4: =IF('Raw Data'!O4="",0,'Raw Data'!O4) -> 0.3 | G4: =ROUND('Raw Data'!P4,2) -> 66.88 | H4: =IF('Raw Data'!S4="","Medium",'Raw Data'!S4) -> High | I4: =IF(E4<100,"Small",IF(E4<500,"Medium",IF(E4<1500,"Large","Very Large"))) -> Large
A5: ='Raw Data'!A5 -> ORD-12634 | B5: =IFERROR(DATEVALUE('Raw Data'!B5),"Check Format") -> 45269 | C5: =IF('Raw Data'!E5="",IFERROR(INDEX('Raw Data'!$E$2:$E$501,MATCH('Raw Data'!D5,'Raw Data'!$D$2:$D$501,0)),"Unknown Customer"),'Raw Data'!E5) -> Amy Miller | D5: =PROPER(TRIM('Raw Data'!G5)) -> Albany | E5: =ROUND(VALUE(SUBSTITUTE(TRIM('Raw Data'!M5),"$","")),2) -> 206.7 | F5: =IF('Raw Data'!O5="",0,'Raw Data'!O5) -> 0.3 | G5: =ROUND('Raw Data'!P5,2) -> -4.43 | H5: =IF('Raw Data'!S5="","Medium",'Raw Data'!S5) -> Critical | I5: =IF(E5<100,"Small",IF(E5<500,"Medium",IF(E5<1500,"Large","Very Large"))) -> Medium
A6: ='Raw Data'!A6 -> ORD-14527 | B6: =IFERROR(DATEVALUE('Raw Data'!B6),"Check Format") -> 45960 | C6: =IF('Raw Data'!E6="",IFERROR(INDEX('Raw Data'!$E$2:$E$501,MATCH('Raw Data'!D6,'Raw Data'!$D$2:$D$501,0)),"Unknown Customer"),'Raw Data'!E6) -> Melissa Abbott | D6: =PROPER(TRIM('Raw Data'!G6)) -> Norfolk | E6: =ROUND(VALUE(SUBSTITUTE(TRIM('Raw Data'!M6),"$","")),2) -> 6846.35 | F6: =IF('Raw Data'!O6="",0,'Raw Data'!O6) -> 0 | G6: =ROUND('Raw Data'!P6,2) -> 1973.68 | H6: =IF('Raw Data'!S6="","Medium",'Raw Data'!S6) -> Low | I6: =IF(E6<100,"Small",IF(E6<500,"Medium",IF(E6<1500,"Large","Very Large"))) -> Very Large
A7: ='Raw Data'!A7 -> ORD-4886 | B7: =IFERROR(DATEVALUE('Raw Data'!B7),"Check Format") -> Check Format | C7: =IF('Raw Data'!E7="",IFERROR(INDEX('Raw Data'!$E$2:$E$501,MATCH('Raw Data'!D7,'Raw Data'!$D$2:$D$501,0)),"Unknown Customer"),'Raw Data'!E7) -> Katie Suarez | D7: =PROPER(TRIM('Raw Data'!G7)) -> Richmond | E7: =ROUND(VALUE(SUBSTITUTE(TRIM('Raw Data'!M7),"$","")),2) -> 209.4 | F7: =IF('Raw Data'!O7="",0,'Raw Data'!O7) -> 0 | G7: =ROUND('Raw Data'!P7,2) -> 0 | H7: =IF('Raw Data'!S7="","Medium",'Raw Data'!S7) -> Critical | I7: =IF(E7<100,"Small",IF(E7<500,"Medium",IF(E7<1500,"Large","Very Large"))) -> Medium
A8: ='Raw Data'!A8 -> ORD-5268 | B8: =IFERROR(DATEVALUE('Raw Data'!B8),"Check Format") -> 45187 | C8: =IF('Raw Data'!E8="",IFERROR(INDEX('Raw Data'!$E$2:$E$501,MATCH('Raw Data'!D8,'Raw Data'!$D$2:$D$501,0)),"Unknown Customer"),'Raw Data'!E8) -> Todd Reynolds | D8: =PROPER(TRIM('Raw Data'!G8)) -> Las Vegas | E8: =ROUND(VALUE(SUBSTITUTE(TRIM('Raw Data'!M8),"$","")),2) -> 2705.92 | F8: =IF('Raw Data'!O8="",0,'Raw Data'!O8) -> 0 | G8: =ROUND('Raw Data'!P8,2) -> 1214.63 | H8: =IF('Raw Data'!S8="","Medium",'Raw Data'!S8) -> Medium | I8: =IF(E8<100,"Small",IF(E8<500,"Medium",IF(E8<1500,"Large","Very Large"))) -> Very Large
A9: ='Raw Data'!A9 -> ORD-12605 | B9: =IFERROR(DATEVALUE('Raw Data'!B9),"Check Format") -> Check Format | C9: =IF('Raw Data'!E9="",IFERROR(INDEX('Raw Data'!$E$2:$E$501,MATCH('Raw Data'!D9,'Raw Data'!$D$2:$D$501,0)),"Unknown Customer"),'Raw Data'!E9) -> Zachary Hicks | D9: =PROPER(TRIM('Raw Data'!G9)) -> San Antonio | E9: =ROUND(VALUE(SUBSTITUTE(TRIM('Raw Data'!M9),"$","")),2) -> 3137.44 | F9: =IF('Raw Data'!O9="",0,'Raw Data'!O9) -> 0 | G9: =ROUND('Raw Data'!P9,2) -> 1380.59 | H9: =IF('Raw Data'!S9="","Medium",'Raw Data'!S9) -> Critical | I9: =IF(E9<100,"Small",IF(E9<500,"Medium",IF(E9<1500,"Large","Very Large"))) -> Very Large
A10: ='Raw Data'!A10 -> ORD-11390 | B10: =IFERROR(DATEVALUE('Raw Data'!B10),"Check Format") -> 46057 | C10: =IF('Raw Data'!E10="",IFERROR(INDEX('Raw Data'!$E$2:$E$501,MATCH('Raw Data'!D10,'Raw Data'!$D$2:$D$501,0)),"Unknown Customer"),'Raw Data'!E10) -> Christine Parker | D10: =PROPER(TRIM('Raw Data'!G10)) -> Worcester | E10: =ROUND(VALUE(SUBSTITUTE(TRIM('Raw Data'!M10),"$","")),2) -> 110.97 | F10: =IF('Raw Data'!O10="",0,'Raw Data'!O10) -> 0 | G10: =ROUND('Raw Data'!P10,2) -> 19.56 | H10: =IF('Raw Data'!S10="","Medium",'Raw Data'!S10) -> Low | I10: =IF(E10<100,"Small",IF(E10<500,"Medium",IF(E10<1500,"Large","Very Large"))) -> Medium
A11: ='Raw Data'!A11 -> ORD-7268 | B11: =IFERROR(DATEVALUE('Raw Data'!B11),"Check Format") -> 46237 | C11: =IF('Raw Data'!E11="",IFERROR(INDEX('Raw Data'!$E$2:$E$501,MATCH('Raw Data'!D11,'Raw Data'!$D$2:$D$501,0)),"Unknown Customer"),'Raw Data'!E11) -> Robert Potter | D11: =PROPER(TRIM('Raw Data'!G11)) -> Lexington | E11: =ROUND(VALUE(SUBSTITUTE(TRIM('Raw Data'!M11),"$","")),2) -> 104.91 | F11: =IF('Raw Data'!O11="",0,'Raw Data'!O11) -> 0.1 | G11: =ROUND('Raw Data'!P11,2) -> 27.54 | H11: =IF('Raw Data'!S11="","Medium",'Raw Data'!S11) -> Medium | I11: =IF(E11<100,"Small",IF(E11<500,"Medium",IF(E11<1500,"Large","Very Large"))) -> Medium
A12: ='Raw Data'!A12 -> ORD-13637 | B12: =IFERROR(DATEVALUE('Raw Data'!B12),"Check Format") -> Check Format | C12: =IF('Raw Data'!E12="",IFERROR(INDEX('Raw Data'!$E$2:$E$501,MATCH('Raw Data'!D12,'Raw Data'!$D$2:$D$501,0)),"Unknown Customer"),'Raw Data'!E12) -> Dawn Rivera | D12: =PROPER(TRIM('Raw Data'!G12)) -> Springfield | E12: =ROUND(VALUE(SUBSTITUTE(TRIM('Raw Data'!M12),"$","")),2) -> 24.37 | F12: =IF('Raw Data'!O12="",0,'Raw Data'!O12) -> 0.5 | G12: =ROUND('Raw Data'!P12,2) -> -5.2 | H12: =IF('Raw Data'!S12="","Medium",'Raw Data'!S12) -> Low | I12: =IF(E12<100,"Small",IF(E12<500,"Medium",IF(E12<1500,"Large","Very Large"))) -> Small
A13: ='Raw Data'!A13 -> ORD-11892 | B13: =IFERROR(DATEVALUE('Raw Data'!B13),"Check Format") -> Check Format | C13: =IF('Raw Data'!E13="",IFERROR(INDEX('Raw Data'!$E$2:$E$501,MATCH('Raw Data'!D13,'Raw Data'!$D$2:$D$501,0)),"Unknown Customer"),'Raw Data'!E13) -> Christopher Guerra | D13: =PROPER(TRIM('Raw Data'!G13)) -> St. Louis | E13: =ROUND(VALUE(SUBSTITUTE(TRIM('Raw Data'!M13),"$","")),2) -> 1051.92 | F13: =IF('Raw Data'!O13="",0,'Raw Data'!O13) -> 0 | G13: =ROUND('Raw Data'!P13,2) -> 360.56 | H13: =IF('Raw Data'!S13="","Medium",'Raw Data'!S13) -> Medium | I13: =IF(E13<100,"Small",IF(E13<500,"Medium",IF(E13<1500,"Large","Very Large"))) -> Large
... A501: ='Raw Data'!A501 -> ORD-14622 | B501: =IFERROR(DATEVALUE('Raw Data'!B501),"Check Format") -> Check Format | C501: =IF('Raw Data'!E501="",IFERROR(INDEX('Raw Data'!$E$2:$E$501,MATCH('Raw Data'!D501,'Raw Data'!$D$2:$D$501,0)),"Unknown Customer"),'Raw Data'!E501) -> Eugene Baldwin | D501: =PROPER(TRIM('Raw Data'!G501)) -> Norfolk | E501: =ROUND(VALUE(SUBSTITUTE(TRIM('Raw Data'!M501),"$","")),2) -> 8561.6 | F501: =IF('Raw Data'!O501="",0,'Raw Data'!O501) -> 0 | G501: =ROUND('Raw Data'!P501,2) -> 1492.65 | H501: =IF('Raw Data'!S501="","Medium",'Raw Data'!S501) -> Critical | I501: =IF(E501<100,"Small",IF(E501<500,"Medium",IF(E501<1500,"Large","Very Large"))) -> Very Large

Sheet Summary (SUMIF-COUNTIF)
A1: Order Priority | B1: Order Count (COUNTIF) | C1: Total Profit (SUMIF)
A2: Low | B2: =COUNTIF('Cleaning Formulas'!H2:H501,A2) -> 131 | C2: =ROUND(SUMIF('Cleaning Formulas'!H2:H501,A2,'Cleaning Formulas'!G2:G501),2) -> 21228.71
A3: Medium | B3: =COUNTIF('Cleaning Formulas'!H2:H501,A3) -> 136 | C3: =ROUND(SUMIF('Cleaning Formulas'!H2:H501,A3,'Cleaning Formulas'!G2:G501),2) -> 21468.61
A4: High | B4: =COUNTIF('Cleaning Formulas'!H2:H501,A4) -> 111 | C4: =ROUND(SUMIF('Cleaning Formulas'!H2:H501,A4,'Cleaning Formulas'!G2:G501),2) -> 15522.01
A5: Critical | B5: =COUNTIF('Cleaning Formulas'!H2:H501,A5) -> 122 | C5: =ROUND(SUMIF('Cleaning Formulas'!H2:H501,A5,'Cleaning Formulas'!G2:G501),2) -> 24027.72
A8: Order Value Tier | B8: Count | C8: Avg Profit (SUMIFS/COUNTIFS)
A9: Small | B9: =COUNTIF('Cleaning Formulas'!I2:I501,A9) -> 67 | C9: =IFERROR(ROUND(SUMIFS('Cleaning Formulas'!G2:G501,'Cleaning Formulas'!I2:I501,A9)/B9,2),0) -> 4.19
A10: Medium | B10: =COUNTIF('Cleaning Formulas'!I2:I501,A10) -> 157 | C10: =IFERROR(ROUND(SUMIFS('Cleaning Formulas'!G2:G501,'Cleaning Formulas'!I2:I501,A10)/B10,2),0) -> 30.67
A11: Large | B11: =COUNTIF('Cleaning Formulas'!I2:I501,A11) -> 102 | C11: =IFERROR(ROUND(SUMIFS('Cleaning Formulas'!G2:G501,'Cleaning Formulas'!I2:I501,A11)/B11,2),0) -> 91.16
A12: Very Large | B12: =COUNTIF('Cleaning Formulas'!I2:I501,A12) -> 174 | C12: =IFERROR(ROUND(SUMIFS('Cleaning Formulas'!G2:G501,'Cleaning Formulas'!I2:I501,A12)/B12,2),0) -> 389.96
A15: Note: Sample of 500 raw rows shown for formula demonstration. Full 15,200-row cleaned dataset is produced by Python/data_cleaning.py and stored in Dataset/Cleaned_Data.xlsx.
